Workbook
Name FINISHES_NET_TOTAL: 'Finishes Cover'!$F$24
Name FINISHES_GRAND_TOTAL: 'Finishes Cover'!$F$30
Name ICF_PACKAGE_TOTAL: 'Finishes Cover'!$F$33
Name COMBINED_TOTAL: 'Finishes Cover'!$F$34

Sheet Cover
A10: BILL OF QUANTITIES
A11: ICF KIT · CONCRETE · LABOUR
A14: LAND TO REAR OF 1-8 WESLEY TERRACE, CASTLESIDE
A15: 18-Plot ICF Development · 8 blocks · Castleside, Consett, County Durham DH8 9QB
B17: Quotation Reference | C17: ES26-080
B18: Project | C18: Land to Rear of 1-8 Wesley Terrace, Castleside
B19: House Type | C19: HT01 3B5P (semi pairs + terraces of 3) / HT02 2B4P bungalow
B20: Client | C20: Wannop Developments Ltd
B21: Site Address | C21: Land to Rear of 1-8 Wesley Terrace, Castleside, Consett DH8 9QB
B22: BOQ Issued | C22: 19 October 2026
B23: BOQ Reference | C23: BOQ-ES26-080-001 · Revision 1.0
B24: Prepared by | C24: Tom Smith — BuildEase Manager, Nudura UK
B25: Issued by | C25: Tremco Construction Products Group
B26: Currency | C26: Pound Sterling (GBP) · VAT at 20%
B27: Measurement Convention | C27: RICS New Rules of Measurement (NRM2)
B29: IMPORTANT NOTICE — DISCLAIMER
B30: • This Bill of Quantities is supplied in good faith based on the BuildEase take-off models for Land to Rear of 1-8 Wesley Terrace, Castleside and the associated Tremco CPG quotation.
B31: • ALL QUANTITIES SHOULD BE INDEPENDENTLY CHECKED AND VERIFIED BY THE PROJECT QS / QUANTITY SURVEYOR before tender submission, ordering or contract award.
B32: • This BOQ does NOT include an external render / finish allowance. Any render, coatings or external wall finish must be measured and priced separately.
B33: • Section C (Concrete) volumes are geometric voids — allow ~3% web displacement deduction and ~5% wastage on top when ordering ready-mix.
B34: • Section D (Labour) day estimates are scaled proportionately from a reference project; actual gang productivity will vary with site conditions, weather and trade experience.
B35: • BuildEase, Tremco Construction Products Group and Nudura UK accept no liability for tender or contract outcomes arising from the use of these figures. If in doubt — ask.
B36: • Contact: Tom Smith — BuildEase Manager, Nudura UK — for clarification on any quantity or rate basis in this document.

Sheet Contents
A1: CONTENTS
A4: Section | B4: Description | C4: Sheet | D4: Status
B5: Cover & Project Information | C5: Cover
B6: Contents | C6: Contents
B7: Indicative Programme (Gantt) | C7: Programme | D7: Information
B8: Summary of Tender Pricing | C8: Summary
A9: A | B9: Preliminaries | C9: A_Preliminaries | D9: Contractor priced
A10: B | B10: ICF Kit Supply | C10: B_ICF_Supply | D10: Pre-priced
A11: C | B11: Concrete Supply, Pump & Placement | C11: C_Concrete | D11: Contractor priced
A12: D | B12: Labour — ICF, Floors & Roofs | C12: D_Labour | D12: Contractor priced
A13: F | B13: Reference Data (informative only) | C13: F_Reference | D13: —

Sheet Programme
A1: PROG · INDICATIVE INSTALL PROGRAMME — RESOURCE-LEVELLED, ONE COLUMN PER WORKING DAY
A2: Group-by-group sequential build with a staggered start between groups. ICF install + snag + pour cycles, intermediate floors and roof structure are completed before moving on. Resourcing and durations below are indicative and must be validated by site management. Render / external finish is NOT included in this programme.
F3: W1 | M3: W2 | T3: W3 | AA3: W4 | AH3: W5 | AO3: W6 | AV3: W7 | BC3: W8 | BJ3: W9 | BQ3: W10
A4: Group | B4: Plots | C4: Forms | D4: Weeks | E4: Start wk | F4: M | G4: T | H4: W | I4: T | J4: F | K4: S | L4: S | M4: M | N4: T | O4: W | P4: T | Q4: F | R4: S | S4: S | T4: M | U4: T | V4: W | W4: T | X4: F | Y4: S | Z4: S | AA4: M | AB4: T | AC4: W | AD4: T | AE4: F | AF4: S | AG4: S | AH4: M | AI4: T | AJ4: W | AK4: T | AL4: F | AM4: S | AN4: S | AO4: M | AP4: T | AQ4: W | AR4: T | AS4: F | AT4: S | AU4: S | AV4: M | AW4: T | AX4: W | AY4: T | AZ4: F | BA4: S | BB4: S | BC4: M | BD4: T | BE4: W | BF4: T | BG4: F | BH4: S | BI4: S | BJ4: M | BK4: T | BL4: W | BM4: T | BN4: F | BO4: S | BP4: S | BQ4: M | BR4: T | BS4: W | BT4: T | BU4: F | BV4: S | BW4: S
A5: Block B01 - HT01 semi pair - plots 01, 02 | B5: 2 | C5: 389 | D5: 4 | E5: 1
A6: Block B02 - HT01 terrace of 3 - plots 03, 04, 05 | B6: 3 | C6: 508 | D6: 5 | E6: 1
A7: Block B03 - HT01 terrace of 3 - plots 06, 07, 08 | B7: 3 | C7: 521 | D7: 6 | E7: 1
A8: Block B04 - HT01 semi pair - plots 09, 10 | B8: 2 | C8: 380 | D8: 5 | E8: 2
A9: Block B05 - HT01 terrace of 3 - plots 11, 12, 13 | B9: 3 | C9: 526 | D9: 5 | E9: 3
A10: Block B06 - HT02 bungalow - plots 14 | B10: 1 | C10: 122 | D10: 4 | E10: 4
A11: Block B07 - HT02 bungalow - plots 15 | B11: 1 | C11: 129 | D11: 3 | E11: 5
A12: Block B08 - HT01 terrace of 3 - plots 16, 17, 18 | B12: 3 | C12: 518 | D12: 6 | E12: 5
A14: LEGEND
C15: ICF walls — FB + L1 lifts installed together (erection, snag & pour)
C16: ICF walls — each lift above the first, once the floor below it is in
C17: Concrete pour — 1 day per lift, ICF crew attends, pump on site
C18: Curing — pours held to Fridays where possible so the 2 curing days fall on the weekend; a mid-week pour cures 2 working days
C19: Floor structure — one per intermediate floor (FF, SF …), between wall lifts
C20: Roof structure (all-timber, trusses + rafters)
A22: RESOURCING
A23: • 1 ICF crews of 8 trained installers (each crew = 2 four-man gang-equivalents) erect the wall lifts, moving to the next ready block while a floor is fitted; 1 joinery crew of 3 fits every intermediate floor and roof (Joinery at 1 day per plot for each floor and 1 day per plot for each roof (Tom 19.10.26).). Programme is resource-levelled day by day (white = block waiting for a crew).
A24: • Total ICF site programme: 10 working weeks (ICF erection, floors and roofs). Section A Preliminaries are quantified against this 10-week programme.
A25: • EXTERNAL RENDER / FINISH IS EXCLUDED from this BOQ and this programme. Where a render system is later specified, allow a separate workstream — per BBA guidance, render cannot begin until the concrete core has cured for a minimum of 28 days after the final pour.
A26: • Concrete pump booked on the pour days for each group (see Section C).
A27: • Lead time for BuildEase Pre-Cut Service: 5–6 weeks from order placement; procurement runs in parallel with mobilisation.
A28: • Programme estimates are provided in good faith and must be verified by the project / site management team.

Sheet Summary
A1: SUMMARY OF TENDER PRICING
A3: Section totals are carried forward from each Bill section. Pre-priced columns show values from the associated Tremco CPG quotation; contractor-priced columns populate automatically when rates are entered in the section sheets. This BOQ excludes external render.
A5: Section | B5: Description | C5: Pre-priced (£) | D5: Contractor-priced (£) | E5: Section Total (£)
A6: A | B6: Preliminaries | D6: ='A_Preliminaries'!F1000 | E6: =IF(ISNUMBER(C6),C6,0)+IF(ISNUMBER(D6),D6,0)
A7: B | B7: ICF Kit Supply | C7: 196202.12 | E7: =IF(ISNUMBER(C7),C7,0)+IF(ISNUMBER(D7),D7,0)
A8: C | B8: Concrete Supply, Pump & Placement | D8: ='C_Concrete'!F1000 | E8: =IF(ISNUMBER(C8),C8,0)+IF(ISNUMBER(D8),D8,0)
A9: D | B9: Labour — ICF, Floors & Roofs | D9: ='D_Labour'!F1000 | E9: =IF(ISNUMBER(C9),C9,0)+IF(ISNUMBER(D9),D9,0)
B11: NET TOTAL (excluding VAT) | C11: =SUM(C6:C9) | D11: =SUM(D6:D9) | E11: =SUM(E6:E9)
B12: VAT @ 20% | E12: =E11*0.20
B13: GRAND TOTAL (inclusive of VAT) | E13: =E11+E12
A17: SIGNATURES
A19: Priced by
A20: Tendered by
A21: Approved by

Sheet A_Preliminaries
A1: A · PRELIMINARIES
A2: Items priced per working week against the site programme total of 10 weeks (see Programme sheet). Quantities are pre-populated; the contractor inserts the weekly rate.
A4: Ref | B4: Description | C4: Unit | D4: Qty | E4: Rate (£) | F4: Total (£)
A5: A.1 | B5: Site set-up, fencing, signage, induction & welfare establishment | C5: item | D5: 1 | F5: =IF(AND(ISNUMBER(D5),ISNUMBER(E5)),D5*E5,0)
A6: A.2 | B6: Welfare facilities — canteen, drying, toilets (hire) | C6: wk | D6: 10 | F6: =IF(AND(ISNUMBER(D6),ISNUMBER(E6)),D6*E6,0)
A7: A.3 | B7: Contract management & site supervision | C7: wk | D7: 10 | F7: =IF(AND(ISNUMBER(D7),ISNUMBER(E7)),D7*E7,0)
A8: A.4 | B8: Health & Safety, RAMS, CDM consultancy | C8: wk | D8: 10 | F8: =IF(AND(ISNUMBER(D8),ISNUMBER(E8)),D8*E8,0)
A9: A.5 | B9: Public liability and contract works insurance | C9: item | D9: 1 | F9: =IF(AND(ISNUMBER(D9),ISNUMBER(E9)),D9*E9,0)
A10: A.6 | B10: Scaffolding — independent access for ICF erection | C10: wk | D10: 10 | F10: =IF(AND(ISNUMBER(D10),ISNUMBER(E10)),D10*E10,0)
A11: A.7 | B11: Plant hire — telehandler / forklift for offload & ICF moves | C11: wk | D11: 10 | F11: =IF(AND(ISNUMBER(D11),ISNUMBER(E11)),D11*E11,0)
A12: A.8 | B12: Plant hire — small tools, generators, power & lighting | C12: wk | D12: 10 | F12: =IF(AND(ISNUMBER(D12),ISNUMBER(E12)),D12*E12,0)
A13: A.9 | B13: Hoarding / site enclosure / security | C13: wk | D13: 10 | F13: =IF(AND(ISNUMBER(D13),ISNUMBER(E13)),D13*E13,0)
A14: A.10 | B14: Temporary services — water, power, lighting (hire) | C14: wk | D14: 10 | F14: =IF(AND(ISNUMBER(D14),ISNUMBER(E14)),D14*E14,0)
A15: A.11 | B15: Site clean, waste management & skip rotation | C15: wk | D15: 10 | F15: =IF(AND(ISNUMBER(D15),ISNUMBER(E15)),D15*E15,0)
A16: A.12 | B16: Setting out and surveying — engineer's level checks | C16: wk | D16: 10 | F16: =IF(AND(ISNUMBER(D16),ISNUMBER(E16)),D16*E16,0)
A17: A.13 | B17: Site take-down, hand-over & demobilisation | C17: item | D17: 1 | F17: =IF(AND(ISNUMBER(D17),ISNUMBER(E17)),D17*E17,0)
A18: A.14 | B18: Pre-completion sound test (Approved Document E) | C18: test | F18: =IF(AND(ISNUMBER(D18),ISNUMBER(E18)),D18*E18,0)
A19: A.15 | B19: Air-tightness test (Approved Document L) | C19: test | F19: =IF(AND(ISNUMBER(D19),ISNUMBER(E19)),D19*E19,0)
A20: A.16 | B20: Day works allowance | C20: sum | F20: =IF(AND(ISNUMBER(D20),ISNUMBER(E20)),D20*E20,0)
B22: A — PRELIMINARIES SUBTOTAL | F22: =SUM(F5:F20)
F1000: =F22

Sheet B_ICF_Supply
A1: B · ICF KIT SUPPLY
A2: ICF material supply values are pre-priced from the associated Tremco CPG quotation. Pre-cut service fees are taken from each BuildEase take-off.
A4: Ref | B4: Description | C4: Unit | D4: Qty | E4: Rate (£) | F4: Total (£)
A5: B.1 — ICF Block, Forms & Accessories
A6: B.1 | B6: ICF Materials — Block B01 - HT01 semi pair - plots 01, 02 (2 plot(s), 389 forms) | C6: group | D6: 1 | E6: 21961.23 | F6: =IF(AND(ISNUMBER(D6),ISNUMBER(E6)),D6*E6,0)
A7: B.1 | B7: ICF Materials — Block B02 - HT01 terrace of 3 - plots 03, 04, 05 (3 plot(s), 508 forms) | C7: group | D7: 1 | E7: 28974.06 | F7: =IF(AND(ISNUMBER(D7),ISNUMBER(E7)),D7*E7,0)
A8: B.1 | B8: ICF Materials — Block B03 - HT01 terrace of 3 - plots 06, 07, 08 (3 plot(s), 521 forms) | C8: group | D8: 1 | E8: 29603.35 | F8: =IF(AND(ISNUMBER(D8),ISNUMBER(E8)),D8*E8,0)
A9: B.1 | B9: ICF Materials — Block B04 - HT01 semi pair - plots 09, 10 (2 plot(s), 380 forms) | C9: group | D9: 1 | E9: 21476.07 | F9: =IF(AND(ISNUMBER(D9),ISNUMBER(E9)),D9*E9,0)
A10: B.1 | B10: ICF Materials — Block B05 - HT01 terrace of 3 - plots 11, 12, 13 (3 plot(s), 526 forms) | C10: group | D10: 1 | E10: 29949.87 | F10: =IF(AND(ISNUMBER(D10),ISNUMBER(E10)),D10*E10,0)
A11: B.1 | B11: ICF Materials — Block B06 - HT02 bungalow - plots 14 (1 plot(s), 122 forms) | C11: group | D11: 1 | E11: 6975.24 | F11: =IF(AND(ISNUMBER(D11),ISNUMBER(E11)),D11*E11,0)
A12: B.1 | B12: ICF Materials — Block B07 - HT02 bungalow - plots 15 (1 plot(s), 129 forms) | C12: group | D12: 1 | E12: 7309.7 | F12: =IF(AND(ISNUMBER(D12),ISNUMBER(E12)),D12*E12,0)
A13: B.1 | B13: ICF Materials — Block B08 - HT01 terrace of 3 - plots 16, 17, 18 (3 plot(s), 518 forms) | C13: group | D13: 1 | E13: 29495.39 | F13: =IF(AND(ISNUMBER(D13),ISNUMBER(E13)),D13*E13,0)
A15: B.2 — BuildEase Pre-Cut Service Fee
A16: B.2 | B16: Pre-Cut Service — Block B01 - HT01 semi pair - plots 01, 02 | C16: group | D16: 1 | E16: 1689.77 | F16: =IF(AND(ISNUMBER(D16),ISNUMBER(E16)),D16*E16,0)
A17: B.2 | B17: Pre-Cut Service — Block B02 - HT01 terrace of 3 - plots 03, 04, 05 | C17: group | D17: 1 | E17: 2017.35 | F17: =IF(AND(ISNUMBER(D17),ISNUMBER(E17)),D17*E17,0)
A18: B.2 | B18: Pre-Cut Service — Block B03 - HT01 terrace of 3 - plots 06, 07, 08 | C18: group | D18: 1 | E18: 1322.49 | F18: =IF(AND(ISNUMBER(D18),ISNUMBER(E18)),D18*E18,0)
A19: B.2 | B19: Pre-Cut Service — Block B04 - HT01 semi pair - plots 09, 10 | C19: group | D19: 1 | E19: 1029.5 | F19: =IF(AND(ISNUMBER(D19),ISNUMBER(E19)),D19*E19,0)
A20: B.2 | B20: Pre-Cut Service — Block B05 - HT01 terrace of 3 - plots 11, 12, 13 | C20: group | D20: 1 | E20: 1331.98 | F20: =IF(AND(ISNUMBER(D20),ISNUMBER(E20)),D20*E20,0)
A21: B.2 | B21: Pre-Cut Service — Block B06 - HT02 bungalow - plots 14 | C21: group | D21: 1 | E21: 1116.94 | F21: =IF(AND(ISNUMBER(D21),ISNUMBER(E21)),D21*E21,0)
A22: B.2 | B22: Pre-Cut Service — Block B07 - HT02 bungalow - plots 15 | C22: group | D22: 1 | E22: 657.56 | F22: =IF(AND(ISNUMBER(D22),ISNUMBER(E22)),D22*E22,0)
A23: B.2 | B23: Pre-Cut Service — Block B08 - HT01 terrace of 3 - plots 16, 17, 18 | C23: group | D23: 1 | E23: 1290.28 | F23: =IF(AND(ISNUMBER(D23),ISNUMBER(E23)),D23*E23,0)
A25: B.3 — Haulage
A26: B.3 | B26: Haulage to site — project-wide estimate (TBC on delivery schedule) | C26: item | D26: 1 | E26: 9041.34 | F26: =IF(AND(ISNUMBER(D26),ISNUMBER(E26)),D26*E26,0)
A28: B.4 — Alignment System
A29: B.4 | B29: Alignment System Rental — Block B01 - HT01 semi pair - plots 01, 02 (37 systems) | C29: group | D29: 1 | E29: 96 | F29: =IF(AND(ISNUMBER(D29),ISNUMBER(E29)),D29*E29,0)
A30: B.4 | B30: Alignment System Rental — Block B02 - HT01 terrace of 3 - plots 03, 04, 05 (50 systems) | C30: group | D30: 1 | E30: 144 | F30: =IF(AND(ISNUMBER(D30),ISNUMBER(E30)),D30*E30,0)
A31: B.4 | B31: Alignment System Rental — Block B03 - HT01 terrace of 3 - plots 06, 07, 08 (50 systems) | C31: group | D31: 1 | E31: 144 | F31: =IF(AND(ISNUMBER(D31),ISNUMBER(E31)),D31*E31,0)
A32: B.4 | B32: Alignment System Rental — Block B04 - HT01 semi pair - plots 09, 10 (37 systems) | C32: group | D32: 1 | E32: 96 | F32: =IF(AND(ISNUMBER(D32),ISNUMBER(E32)),D32*E32,0)
A33: B.4 | B33: Alignment System Rental — Block B05 - HT01 terrace of 3 - plots 11, 12, 13 (50 systems) | C33: group | D33: 1 | E33: 144 | F33: =IF(AND(ISNUMBER(D33),ISNUMBER(E33)),D33*E33,0)
A34: B.4 | B34: Alignment System Rental — Block B06 - HT02 bungalow - plots 14 (28 systems) | C34: group | D34: 1 | E34: 96 | F34: =IF(AND(ISNUMBER(D34),ISNUMBER(E34)),D34*E34,0)
A35: B.4 | B35: Alignment System Rental — Block B07 - HT02 bungalow - plots 15 (28 systems) | C35: group | D35: 1 | E35: 96 | F35: =IF(AND(ISNUMBER(D35),ISNUMBER(E35)),D35*E35,0)
A36: B.4 | B36: Alignment System Rental — Block B08 - HT01 terrace of 3 - plots 16, 17, 18 (50 systems) | C36: group | D36: 1 | E36: 144 | F36: =IF(AND(ISNUMBER(D36),ISNUMBER(E36)),D36*E36,0)
B38: B — ICF KIT SUPPLY SUBTOTAL | F38: =SUM(F5:F36)
F1000: =F38

Sheet C_Concrete
A1: C · CONCRETE SUPPLY, PUMP & PLACEMENT
A2: Volumes are geometric void calculations (block length × course height × core thickness). Allow ~3% for plastic web displacement and ~5% wastage when ordering. Rates to be inserted by the contractor.
A4: Ref | B4: Description | C4: Unit | D4: Qty | E4: Rate (£) | F4: Total (£)
A5: C.1 — Ready-Mix Concrete Supply (C28/35 typical to BS 8500)
A6: C.1 | B6: Ready-mix concrete — Block B01 - HT01 semi pair - plots 01, 02 (2 plot(s), geometric void) | C6: m³ | D6: 62.77 | F6: =IF(AND(ISNUMBER(D6),ISNUMBER(E6)),D6*E6,0)
A7: C.1 | B7: Ready-mix concrete — Block B02 - HT01 terrace of 3 - plots 03, 04, 05 (3 plot(s), geometric void) | C7: m³ | D7: 83.05 | F7: =IF(AND(ISNUMBER(D7),ISNUMBER(E7)),D7*E7,0)
A8: C.1 | B8: Ready-mix concrete — Block B03 - HT01 terrace of 3 - plots 06, 07, 08 (3 plot(s), geometric void) | C8: m³ | D8: 85.14 | F8: =IF(AND(ISNUMBER(D8),ISNUMBER(E8)),D8*E8,0)
A9: C.1 | B9: Ready-mix concrete — Block B04 - HT01 semi pair - plots 09, 10 (2 plot(s), geometric void) | C9: m³ | D9: 61.24 | F9: =IF(AND(ISNUMBER(D9),ISNUMBER(E9)),D9*E9,0)
A10: C.1 | B10: Ready-mix concrete — Block B05 - HT01 terrace of 3 - plots 11, 12, 13 (3 plot(s), geometric void) | C10: m³ | D10: 85.99 | F10: =IF(AND(ISNUMBER(D10),ISNUMBER(E10)),D10*E10,0)
A11: C.1 | B11: Ready-mix concrete — Block B06 - HT02 bungalow - plots 14 (1 plot(s), geometric void) | C11: m³ | D11: 18.92 | F11: =IF(AND(ISNUMBER(D11),ISNUMBER(E11)),D11*E11,0)
A12: C.1 | B12: Ready-mix concrete — Block B07 - HT02 bungalow - plots 15 (1 plot(s), geometric void) | C12: m³ | D12: 20 | F12: =IF(AND(ISNUMBER(D12),ISNUMBER(E12)),D12*E12,0)
A13: C.1 | B13: Ready-mix concrete — Block B08 - HT01 terrace of 3 - plots 16, 17, 18 (3 plot(s), geometric void) | C13: m³ | D13: 84.63 | F13: =IF(AND(ISNUMBER(D13),ISNUMBER(E13)),D13*E13,0)
A15: C.2 — Concrete Pump Hire
A16: C.2 | B16: Boom pump hire — Block B01 - HT01 semi pair - plots 01, 02 | C16: day | D16: 2 | F16: =IF(AND(ISNUMBER(D16),ISNUMBER(E16)),D16*E16,0)
A17: C.2 | B17: Boom pump hire — Block B02 - HT01 terrace of 3 - plots 03, 04, 05 | C17: day | D17: 2 | F17: =IF(AND(ISNUMBER(D17),ISNUMBER(E17)),D17*E17,0)
A18: C.2 | B18: Boom pump hire — Block B03 - HT01 terrace of 3 - plots 06, 07, 08 | C18: day | D18: 2 | F18: =IF(AND(ISNUMBER(D18),ISNUMBER(E18)),D18*E18,0)
A19: C.2 | B19: Boom pump hire — Block B04 - HT01 semi pair - plots 09, 10 | C19: day | D19: 2 | F19: =IF(AND(ISNUMBER(D19),ISNUMBER(E19)),D19*E19,0)
A20: C.2 | B20: Boom pump hire — Block B05 - HT01 terrace of 3 - plots 11, 12, 13 | C20: day | D20: 2 | F20: =IF(AND(ISNUMBER(D20),ISNUMBER(E20)),D20*E20,0)
A21: C.2 | B21: Boom pump hire — Block B06 - HT02 bungalow - plots 14 | C21: day | D21: 2 | F21: =IF(AND(ISNUMBER(D21),ISNUMBER(E21)),D21*E21,0)
A22: C.2 | B22: Boom pump hire — Block B07 - HT02 bungalow - plots 15 | C22: day | D22: 2 | F22: =IF(AND(ISNUMBER(D22),ISNUMBER(E22)),D22*E22,0)
A23: C.2 | B23: Boom pump hire — Block B08 - HT01 terrace of 3 - plots 16, 17, 18 | C23: day | D23: 2 | F23: =IF(AND(ISNUMBER(D23),ISNUMBER(E23)),D23*E23,0)
A24: C.2 | B24: Pump mobilisation / demobilisation | C24: item | D24: 1 | F24: =IF(AND(ISNUMBER(D24),ISNUMBER(E24)),D24*E24,0)
A26: C.3 — Concrete Vibration & Placement Plant
A27: C.3 | B27: Internal poker vibrator hire — site duration | C27: wk | D27: 10 | F27: =IF(AND(ISNUMBER(D27),ISNUMBER(E27)),D27*E27,0)
A28: C.3 | B28: Concrete banksman / poker operator | C28: day | F28: =IF(AND(ISNUMBER(D28),ISNUMBER(E28)),D28*E28,0)
B30: C — CONCRETE SUBTOTAL | F30: =SUM(F5:F28)
F1000: =F30

Sheet D_Labour
A1: D · LABOUR — ICF INSTALL, FLOORS & ROOFS
A2: ICF install days scaled proportionately against the Maycroft reference (52.65 forms per gang-day). Rates below are per 4-man gang per day. Floor and roof allowances are taken per group from the project configuration.
A4: Ref | B4: Description | C4: Unit | D4: Qty | E4: Rate (£) | F4: Total (£)
A5: D.1 — ICF Install Gang
A6: D.1 | B6: ICF install — Block B01 - HT01 semi pair - plots 01, 02 (389 forms ÷ 52.65 forms/day = 7.4 gang-days) | C6: gang-day | D6: 7.4 | F6: =IF(AND(ISNUMBER(D6),ISNUMBER(E6)),D6*E6,0)
A7: D.1 | B7: ICF install — Block B02 - HT01 terrace of 3 - plots 03, 04, 05 (508 forms ÷ 52.65 forms/day = 9.6 gang-days) | C7: gang-day | D7: 9.6 | F7: =IF(AND(ISNUMBER(D7),ISNUMBER(E7)),D7*E7,0)
A8: D.1 | B8: ICF install — Block B03 - HT01 terrace of 3 - plots 06, 07, 08 (521 forms ÷ 52.65 forms/day = 9.9 gang-days) | C8: gang-day | D8: 9.9 | F8: =IF(AND(ISNUMBER(D8),ISNUMBER(E8)),D8*E8,0)
A9: D.1 | B9: ICF install — Block B04 - HT01 semi pair - plots 09, 10 (380 forms ÷ 52.65 forms/day = 7.2 gang-days) | C9: gang-day | D9: 7.2 | F9: =IF(AND(ISNUMBER(D9),ISNUMBER(E9)),D9*E9,0)
A10: D.1 | B10: ICF install — Block B05 - HT01 terrace of 3 - plots 11, 12, 13 (526 forms ÷ 52.65 forms/day = 10.0 gang-days) | C10: gang-day | D10: 10 | F10: =IF(AND(ISNUMBER(D10),ISNUMBER(E10)),D10*E10,0)
A11: D.1 | B11: ICF install — Block B06 - HT02 bungalow - plots 14 (122 forms ÷ 52.65 forms/day = 2.3 gang-days) | C11: gang-day | D11: 2.3 | F11: =IF(AND(ISNUMBER(D11),ISNUMBER(E11)),D11*E11,0)
A12: D.1 | B12: ICF install — Block B07 - HT02 bungalow - plots 15 (129 forms ÷ 52.65 forms/day = 2.5 gang-days) | C12: gang-day | D12: 2.5 | F12: =IF(AND(ISNUMBER(D12),ISNUMBER(E12)),D12*E12,0)
A13: D.1 | B13: ICF install — Block B08 - HT01 terrace of 3 - plots 16, 17, 18 (518 forms ÷ 52.65 forms/day = 9.8 gang-days) | C13: gang-day | D13: 9.8 | F13: =IF(AND(ISNUMBER(D13),ISNUMBER(E13)),D13*E13,0)
A14: D.1 | B14: Snag, pour & cure attendance (30% allowance, project total) | C14: gang-day | D14: 17.6 | F14: =IF(AND(ISNUMBER(D14),ISNUMBER(E14)),D14*E14,0)
A16: D.2 — Floor Structure Labour (metal-web joists, top-hung balloon frame)
A17: D.2 | B17: Floor structure — Block B01 - HT01 semi pair - plots 01, 02 (1 floor × 2 gang-days) | C17: gang-day | D17: 2 | F17: =IF(AND(ISNUMBER(D17),ISNUMBER(E17)),D17*E17,0)
A18: D.2 | B18: Floor structure — Block B02 - HT01 terrace of 3 - plots 03, 04, 05 (1 floor × 3 gang-days) | C18: gang-day | D18: 3 | F18: =IF(AND(ISNUMBER(D18),ISNUMBER(E18)),D18*E18,0)
A19: D.2 | B19: Floor structure — Block B03 - HT01 terrace of 3 - plots 06, 07, 08 (1 floor × 3 gang-days) | C19: gang-day | D19: 3 | F19: =IF(AND(ISNUMBER(D19),ISNUMBER(E19)),D19*E19,0)
A20: D.2 | B20: Floor structure — Block B04 - HT01 semi pair - plots 09, 10 (1 floor × 2 gang-days) | C20: gang-day | D20: 2 | F20: =IF(AND(ISNUMBER(D20),ISNUMBER(E20)),D20*E20,0)
A21: D.2 | B21: Floor structure — Block B05 - HT01 terrace of 3 - plots 11, 12, 13 (1 floor × 3 gang-days) | C21: gang-day | D21: 3 | F21: =IF(AND(ISNUMBER(D21),ISNUMBER(E21)),D21*E21,0)
A22: D.2 | B22: Floor structure — Block B08 - HT01 terrace of 3 - plots 16, 17, 18 (1 floor × 3 gang-days) | C22: gang-day | D22: 3 | F22: =IF(AND(ISNUMBER(D22),ISNUMBER(E22)),D22*E22,0)
A24: D.3 — Roof Structure Labour (trusses + rafters, all-timber)
A25: D.3 | B25: Roof structure — Block B01 - HT01 semi pair - plots 01, 02 | C25: gang-day | D25: 2 | F25: =IF(AND(ISNUMBER(D25),ISNUMBER(E25)),D25*E25,0)
A26: D.3 | B26: Roof structure — Block B02 - HT01 terrace of 3 - plots 03, 04, 05 | C26: gang-day | D26: 3 | F26: =IF(AND(ISNUMBER(D26),ISNUMBER(E26)),D26*E26,0)
A27: D.3 | B27: Roof structure — Block B03 - HT01 terrace of 3 - plots 06, 07, 08 | C27: gang-day | D27: 3 | F27: =IF(AND(ISNUMBER(D27),ISNUMBER(E27)),D27*E27,0)
A28: D.3 | B28: Roof structure — Block B04 - HT01 semi pair - plots 09, 10 | C28: gang-day | D28: 2 | F28: =IF(AND(ISNUMBER(D28),ISNUMBER(E28)),D28*E28,0)
A29: D.3 | B29: Roof structure — Block B05 - HT01 terrace of 3 - plots 11, 12, 13 | C29: gang-day | D29: 3 | F29: =IF(AND(ISNUMBER(D29),ISNUMBER(E29)),D29*E29,0)
A30: D.3 | B30: Roof structure — Block B06 - HT02 bungalow - plots 14 | C30: gang-day | D30: 1 | F30: =IF(AND(ISNUMBER(D30),ISNUMBER(E30)),D30*E30,0)
A31: D.3 | B31: Roof structure — Block B07 - HT02 bungalow - plots 15 | C31: gang-day | D31: 1 | F31: =IF(AND(ISNUMBER(D31),ISNUMBER(E31)),D31*E31,0)
A32: D.3 | B32: Roof structure — Block B08 - HT01 terrace of 3 - plots 16, 17, 18 | C32: gang-day | D32: 3 | F32: =IF(AND(ISNUMBER(D32),ISNUMBER(E32)),D32*E32,0)
B34: D — LABOUR SUBTOTAL | F34: =SUM(F5:F32)
F1000: =F34

Sheet F_Reference
A1: F · REFERENCE DATA (informative only)
A2: Per-group quantities calculated from the BuildEase take-off models. Values feed into Sections C and D. Render is excluded from this BOQ.
A4: Group | B4: Plots | C4: Forms | D4: Concrete (m³) | E4: ICF install days | F4: Floor + Roof days | G4: Pre-cut (£)
A5: Block B01 - HT01 semi pair - plots 01, 02 | B5: 2 | C5: 389 | D5: 62.77 | E5: 7.4 | F5: 4 | G5: 1689.77
A6: Block B02 - HT01 terrace of 3 - plots 03, 04, 05 | B6: 3 | C6: 508 | D6: 83.05 | E6: 9.6 | F6: 6 | G6: 2017.35
A7: Block B03 - HT01 terrace of 3 - plots 06, 07, 08 | B7: 3 | C7: 521 | D7: 85.14 | E7: 9.9 | F7: 6 | G7: 1322.49
A8: Block B04 - HT01 semi pair - plots 09, 10 | B8: 2 | C8: 380 | D8: 61.24 | E8: 7.2 | F8: 4 | G8: 1029.5
A9: Block B05 - HT01 terrace of 3 - plots 11, 12, 13 | B9: 3 | C9: 526 | D9: 85.99 | E9: 10 | F9: 6 | G9: 1331.98
A10: Block B06 - HT02 bungalow - plots 14 | B10: 1 | C10: 122 | D10: 18.92 | E10: 2.3 | F10: 1 | G10: 1116.94
A11: Block B07 - HT02 bungalow - plots 15 | B11: 1 | C11: 129 | D11: 20 | E11: 2.5 | F11: 1 | G11: 657.56
A12: Block B08 - HT01 terrace of 3 - plots 16, 17, 18 | B12: 3 | C12: 518 | D12: 84.63 | E12: 9.8 | F12: 6 | G12: 1290.28
A13: SITE | B13: 18 | C13: 3093 | D13: 501.75 | E13: 58.7 | F13: 34 | G13: 10455.87
A16: PER-LIFT FORM BREAKDOWN
A17: Group | B17: Lift | C17: 4" Std | D17: 6" XR35 str | E17: 6" XR35 cnr | F17: 10" Std | G17: Lift total
A18: Block B01 - HT01 semi pair - plots 01, 02 | B18: FB | C18: 0 | D18: 57 | E18: 11 | F18: 0 | G18: 68
A19: Block B01 - HT01 semi pair - plots 01, 02 | B19: L1 | C19: 0 | D19: 109 | E19: 24 | F19: 0 | G19: 133
A20: Block B01 - HT01 semi pair - plots 01, 02 | B20: L2 | C20: 0 | D20: 164 | E20: 24 | F20: 0 | G20: 188
A21: Block B02 - HT01 terrace of 3 - plots 03, 04, 05 | B21: FB | C21: 0 | D21: 70 | E21: 10 | F21: 0 | G21: 80
A22: Block B02 - HT01 terrace of 3 - plots 03, 04, 05 | B22: L1 | C22: 0 | D22: 154 | E22: 24 | F22: 0 | G22: 178
A23: Block B02 - HT01 terrace of 3 - plots 03, 04, 05 | B23: L2 | C23: 0 | D23: 226 | E23: 24 | F23: 0 | G23: 250
A24: Block B03 - HT01 terrace of 3 - plots 06, 07, 08 | B24: FB | C24: 0 | D24: 81 | E24: 12 | F24: 0 | G24: 93
A25: Block B03 - HT01 terrace of 3 - plots 06, 07, 08 | B25: L1 | C25: 0 | D25: 154 | E25: 24 | F25: 0 | G25: 178
A26: Block B03 - HT01 terrace of 3 - plots 06, 07, 08 | B26: L2 | C26: 0 | D26: 226 | E26: 24 | F26: 0 | G26: 250
A27: Block B04 - HT01 semi pair - plots 09, 10 | B27: FB | C27: 0 | D27: 48 | E27: 11 | F27: 0 | G27: 59
A28: Block B04 - HT01 semi pair - plots 09, 10 | B28: L1 | C28: 0 | D28: 109 | E28: 24 | F28: 0 | G28: 133
A29: Block B04 - HT01 semi pair - plots 09, 10 | B29: L2 | C29: 0 | D29: 164 | E29: 24 | F29: 0 | G29: 188
... A39: Block B08 - HT01 terrace of 3 - plots 16, 17, 18 | B39: L2 | C39: 0 | D39: 226 | E39: 24 | F39: 0 | G39: 250
A42: GEOMETRIC CONSTANTS & CALCULATION BASIS
A43: Block length | C43: 2.438 m | E43: 96 inches
A44: Course height | C44: 0.4574 m | E44: 18 inches
A45: 4" Std straight volume | C45: 0.1133 m³ | E45: =length × course × core
A46: 6" XR35 straight volume | C46: 0.1699 m³ | E46: =length × course × core
A47: 10" Std straight volume | C47: 0.2832 m³ | E47: =length × course × core
A48: 4" Std corner volume | C48: 0.0511 m³ | E48: L-void; long 31.625" / short 15.625"
A49: 6" XR35 corner volume | C49: 0.1133 m³ | E49: L-void; long 43" / short 27"
A50: Maycroft install rate | C50: 52.65 forms/day | E50: Reference: 1053 forms ÷ 20 days

Sheet Finishes Cover
C1: Bill of Quantities Package - Finishes & Ancillary Trades
C2: ES26-080 | Land to Rear of 1-8 Wesley Terrace, Castleside | Wannop Developments Ltd
A4: DISCLAIMER: This information is supplied in good faith for guidance and coordination only. It is not part of the Nudura ICF price and must be checked and verified by the appropriate professional (quantity surveyor, designer, engineer or supplier) before use. Only the Nudura ICF formwork and associated accessories are included in our price. Quantities are measured from the quotation models and the SK11A drawings (DRAFT); no allowance for waste is included unless stated. Quantities are per block for each block type; the Site total multiplies by the number of blocks. Rates and amounts are by others.
A6: Project | B6: Land to Rear of 1-8 Wesley Terrace, Castleside
A7: Site | B7: Land to Rear of 1-8 Wesley Terrace, Castleside, County Durham DH8 9QB
A8: Client | B8: Wannop Developments Ltd
A9: Architect | B9: Code L6 Architecture Ltd (24-014, drawings SK11A / 10G, DRAFT)
A10: Quotation ref | B10: ES26-080
A11: Document | B11: Bill of Quantities Package - Finishes & Ancillary Trades
A12: Issue | B12: 01 (19/10/2026)
A13: Scope | B13: 18 dwellings in 8 blocks: HT01 3-bed 2-storey houses as 2 semi pairs (B01, B04) and 4 terraces of 3 (B02, B03, B05 brick; B08 stone, plots 16-18); HT02 2-bed detached bungalows (B06, B07, plots 14-15)
A14: Prepared by | B14: BuildEase (Tremco CPG UK) - BuildEase Design Suite quotation models
A15: Status | B15: FOR INFORMATION, COORDINATION AND PRICING BY OTHERS - rates blank; NOT part of the Nudura ICF price
A17: PACKAGE OVERVIEW - pricing by others (all amounts formula-linked to each bill's Package Summary)
A18: Bill | B18: Package | C18: Code / NRM2 | D18: Supply £ | E18: Install £ | F18: Total £
A19: Bill 1 | B19: External Wall Finishes - Brick & Stone Slips | C19: CLD NRM2 21 | D19: ='Bill 1 External Finishes'!K44 | E19: ='Bill 1 External Finishes'!L44 | F19: ='Bill 1 External Finishes'!M44
A20: Bill 2 | B20: Internal Linings - Plasterboard, Tape, Beads & Skim | C20: DRY NRM2 28 | D20: ='Bill 2 Internal Linings'!K40 | E20: ='Bill 2 Internal Linings'!L40 | F20: ='Bill 2 Internal Linings'!M40
A21: Bill 3 | B21: Internal Doors & Ironmongery | C21: JOI NRM2 24 | D21: ='Bill 3 Doors'!K31 | E21: ='Bill 3 Doors'!L31 | F21: ='Bill 3 Doors'!M31
A22: Bill 4 | B22: Joinery - Skirtings, Architraves, Window Boards & Loft Hatches | C22: JOI NRM2 22 | D22: ='Bill 4 Joinery'!K44 | E22: ='Bill 4 Joinery'!L44 | F22: ='Bill 4 Joinery'!M44
A23: Bill 5 | B23: Timber Stud Partitions - Framing, Openings, Pattresses & Fixings | C23: JOI NRM2 16 | D23: ='Bill 5 Partitions'!K47 | E23: ='Bill 5 Partitions'!L47 | F23: ='Bill 5 Partitions'!M47
A24: GRAND TOTAL - finishes / ancillary trades, net (excl. VAT) | D24: =SUM(D19:D23) | E24: =SUM(E19:E23) | F24: =SUM(F19:F23)
A26: Optional additions (enter %; blank = 0) | C26: % | F26: Amount £
A27: Preliminaries | B27: on the finishes net grand total | F27: =(F24)*N(C27)
A28: Overheads & profit | B28: on net total + preliminaries | F28: =(F24+F27)*N(C28)
A29: Contingency | B29: on net total + preliminaries + OH&P | F29: =(F24+F27+F28)*N(C29)
A30: GRAND TOTAL finishes incl. preliminaries, OH&P and contingency (excl. VAT) | F30: =F24+F27+F28+F29
A32: ICF PACKAGE HOOK - BuildEase BOQ Builder (ICF kit, concrete, labour, preliminaries, programme)
A33: Nudura ICF package (BuildEase BOQ Builder) | F33: ='Summary'!$E$11
A34: COMBINED TOTAL - finishes package (incl. additions) + ICF package, excl. VAT | F34: =F30+N(F33)
A35: Pale-yellow cells are the only inputs (rates on each bill sheet, percentages and the ICF hook here). Everything else is a locked formula (protection has no password). Schedules A to D are reference only and are not priced. Named cells: FINISHES_NET_TOTAL, FINISHES_GRAND_TOTAL, ICF_PACKAGE_TOTAL, COMBINED_TOTAL.
A37: IMPORTANT - This information is supplied in good faith for guidance and coordination only. It is not part of the Nudura ICF price and must be checked and verified by the appropriate professional (quantity surveyor, designer, engineer or supplier) before use. Only the Nudura ICF formwork and associated accessories are included in our price. Quantities are measured from the quotation models and the SK11A drawings (DRAFT); no allowance for waste is included unless stated. Quantities are per block for each block type; the Site total multiplies by the number of blocks. Rates and amounts are by others.
A39: KEY QUANTITIES (site totals, 8 blocks / 18 plots, net; linked to the bills)
A40: Brick slips, walls (net, excl. reveals) | D40: ='Bill 1 External Finishes'!H10+'Bill 1 External Finishes'!H11+'Bill 1 External Finishes'!H12+'Bill 1 External Finishes'!H13 | E40: m2
A41: Stone slips, walls (net, excl. reveals) | D41: ='Bill 1 External Finishes'!H22+'Bill 1 External Finishes'!H23+'Bill 1 External Finishes'!H24 | E41: m2
A42: Plasterboard, walls, reveals and bands (net) | D42: ='Bill 2 Internal Linings'!H10+'Bill 2 Internal Linings'!H11+'Bill 2 Internal Linings'!H12+'Bill 2 Internal Linings'!H13+'Bill 2 Internal Linings'!H14+'Bill 2 Internal Linings'!H15+'Bill 2 Internal Linings'!H16+'Bill 2 Internal Linings'!H17+'Bill 2 Internal Linings'!H18 | E42: m2
A43: Plasterboard, ceilings and stair soffits (net) | D43: ='Bill 2 Internal Linings'!H21+'Bill 2 Internal Linings'!H22+'Bill 2 Internal Linings'!H23+'Bill 2 Internal Linings'!H24 | E43: m2
A44: Skim coat | D44: ='Bill 2 Internal Linings'!H31 | E44: m2
A45: Internal doorsets | D45: ='Bill 3 Doors'!H10+'Bill 3 Doors'!H11+'Bill 3 Doors'!H12+'Bill 3 Doors'!H13 | E45: nr
A46: Skirting | D46: ='Bill 4 Joinery'!H24 | E46: m
A47: Architrave | D47: ='Bill 4 Joinery'!H27+'Bill 4 Joinery'!H28 | E47: m
...

Sheet General Notes
B1: General Notes, Measurement Basis, Assumptions & Exclusions
B2: ES26-080 | Land to Rear of 1-8 Wesley Terrace, Castleside | Wannop Developments Ltd
A4: DISCLAIMER: This information is supplied in good faith for guidance and coordination only. It is not part of the Nudura ICF price and must be checked and verified by the appropriate professional (quantity surveyor, designer, engineer or supplier) before use. Only the Nudura ICF formwork and associated accessories are included in our price. Quantities are measured from the quotation models and the SK11A drawings (DRAFT); no allowance for waste is included unless stated. Quantities are per block for each block type; the Site total multiplies by the number of blocks. Rates and amounts are by others.
A6: 1 Purpose and status
A7: 1.1 | B7: This package presents the finishes and ancillary-trade quantities measured by BuildEase alongside the Nudura ICF quotation for Land to Rear of 1-8 Wesley Terrace, Castleside (ref ES26-080). It is set out in the form of a Bill of Quantities so that the client, their quantity surveyor and trade contractors can price and coordinate the works.
A8: 1.2 | B8: Status: FOR INFORMATION, COORDINATION AND PRICING BY OTHERS. Supply and install rates are left blank deliberately - BuildEase / Tremco CPG are not pricing these trades. The Excel workbook is a live pricing document: enter rates and every amount, section subtotal, package total and the cover overview update by formula.
A9: 1.3 | B9: The ICF kit, concrete core, pumping and ICF / floor / roof labour and the build programme are in the separate BuildEase BOQ Builder workbook. The cover of this workbook carries a named hook (ICF_PACKAGE_TOTAL) so the two can be combined into one workbook and one grand total.
A10: 1.4 | B10: This information is supplied in good faith for guidance and coordination only. It is not part of the Nudura ICF price and must be checked and verified by the appropriate professional (quantity surveyor, designer, engineer or supplier) before use. Only the Nudura ICF formwork and associated accessories are included in our price.
A11: 1.5 | B11: Quantities are measured from the quotation models and the SK11A drawings (DRAFT); no allowance for waste is included unless stated. Quantities are per block for each block type; the Site total multiplies by the number of blocks. Rates and amounts are by others.
A13: 2 Basis of measurement
A14: 2.1 | B14: Measured generally in accordance with the principles of NRM2 (RICS New Rules of Measurement, Detailed measurement for building works): work measured net as fixed in position, items grouped by work section, units m / m2 / nr / item. NRM2 is referenced for structure only; descriptions are BuildEase's own.
A15: 2.2 | B15: Quantities are NET. No allowance for waste, laps, cutting or breakage is included unless stated. Where useful an "Order guide" with a stated waste % is given in the Notes column; it is guidance only.
A16: 2.3 | B16: Quantity columns: one column PER BLOCK for each block type - T01_SEMI (B01, B04; plots 01-02, 09-10), T01_TER3 brick (B02, B03, B05; plots 03-08, 11-13), T01_TER3 stone (B08; plots 16-18) and T02_BUNG (B06, B07; plots 14, 15). The Site total = sum of (per-block quantity x number of blocks) and is a live formula. Mid-terrace units differ slightly from end units (party walls both sides); Schedule C lists the key quantities plot by plot.
A17: 2.4 | B17: Sources: Code L6 drawings 24-014-SK11A (house types, plans and elevations, 1:100 @ A1, DRAFT) and 24-014-10G (site plan, DRAFT); the BuildEase quotation models per block type (03_Models WD_T01_SEMI / WD_T01_TER3 / WD_T02_BUNG) through their specs (04_Logs/specs WD_spec*.json, WD_partitions.json) and build reports (04_Logs/build: floor / stair, TLSTF partition, pattress and noggin reports). Measured offline by 05_Scripts/wd_xi_takeoff.py; presented by wd_boq.py.
A19: 3 Assumptions
A20: 3.1 | B20: Walls: external ICF 6in XR35 (355.6 mm) set out on the drawn outer face; party walls 6in Std (285.75 mm). External finish: brick to units 01-15 (incl. bungalows 14-15) and stone to units 16-18 (SK11A elevations), taken as slip systems on the ICF - the ICF occupies the drawn wall thickness, so a full masonry outer leaf would need the set-out changed (confirm with the architect).
A21: 3.2 | B21: Windows / doors set 1/3 back from the outer ICF face (118.5 mm). External reveal = set-back + slip (brick 25 mm / stone 30 mm). Internal reveal = 195 mm (ICF less set-back less frame 70 plus lining 27.5).
A22: 3.3 | B22: Finish heights: from DPC (FFL - 150) to eaves 5,320 (HT01) / 2,320 (HT02); HT01 gables to the drawn brick apex 8,255. Lining heights: HT01 GF 2,425 (u/s joists), FF 2,700-5,370; HT02 2,336.
A23: 3.4 | B23: Plasterboard: 12.5 mm wallboard to ICF faces (MR in wet rooms); 15 mm sound / fire board to party walls; 15 mm each side of the 38 x 89 stud partitions; 12.5 mm ceilings, plus VCL under the trusses. Board types are proposals.
A24: 3.5 | B24: Doors: 900 / 800 / 700 mm gaps -> 826 / 726 / 626 x 2040 leaves; no fire doors in the houses or bungalows. Cupboard ironmongery counted per leaf; flush bolt per double door (none on this job).
A25: 3.6 | B25: Sloping site: per-block FFL = mean of the four existing corner ground levels + 150 (the stepped-footing rule used in the model). Items 1C are provisional.
A27: 4 Exclusions (not measured in this package)
A28: 4.1 | B28: Nudura ICF formwork and accessories (in the Nudura price - see section 6). Concrete core, pumping, ICF / floor / roof labour and preliminaries are in the BuildEase BOQ Builder ICF + programme workbook.
A29: 4.2 | B29: Supply of windows and external doorsets and cills (listed for coordination only), roof trusses, coverings, soffits, fascias and rainwater goods, FF floor joists and deck, staircases and balustrades, ground-bearing slab / screed / floor insulation.
A30: 4.3 | B30: Floor finishes, decorations, kitchens, sanitaryware, M&E services and builder's work, external works and drainage (other than as 1C).
A31: 4.4 | B31: Fire-stopping, cavity barriers, acoustic / thermal insulation to partitions, floors and lofts, sealants and mastics, except where expressly described.
A33: 5 Items to be confirmed
A34: 5.1 | B34: SK11A and 10G are marked DRAFT - quantities follow the draft drawings and the models built from them.
A35: 5.2 | B35: External finish build-ups (brick slip and stone slip systems over ICF) and whether a full masonry outer leaf is intended.
A36: 5.3 | B36: Final external levels: 1C.1 / 1C.2 are from the existing survey and the FFL rule; re-measure on the designed levels (falls up to 2.25 m within B03 / B05 / B08).
A37: 5.4 | B37: Partition timber (5B) is an estimate - the TLSTF construction extract with cut lengths was not exported for ES26-080.
A38: 5.5 | B38: Floor-noggin blockers (FF partition lines on / beside doubled trimmers) and 6 ceiling-noggin blockers on the bungalow hip set - detail with the floor / truss designers.
A39: 5.6 | B39: Room areas agree with the drawn areas within ~0.4 m2 (finished faces from the ICF set-out on the drawn outer face) - see Schedule A.
A41: 6 What IS in the Nudura price (Quotation ES26-080)
A42: 6.1 | B42: Nudura pre-cut ICF kit for the 8 blocks / 18 plots as modelled in the BuildEase Design Suite (stepped footings per block).
A43: 6.2 | B43: Accessories: VJC clips, fibre tape, protective tape, spray foam, Form Lock and T-junction straps, end caps and lintel closures.
A44: 6.3 | B44: BuildEase Pre-Cut Service: design, coordination, installation drawings, pre-cutting and packaging of forms, field services support.
A45: 6.4 | B45: Nothing in Bills 1 to 5 of this package is included in the Nudura price.
A47: 7 Pricing instructions to tenderers
A48: 7.1 | B48: Each bill item has a SUPPLY rate and an INSTALL rate. Insert rates only in the pale-yellow cells of the Excel workbook: Supply = Site total qty x Supply rate; Install = Site total qty x Install rate; Line total = Supply + Install. Items measured as "item" are lump sums: the rate entered is the amount.
...

Sheet Summary of Bills
C1: Summary of Bills - section breakdown
C2: ES26-080 | Land to Rear of 1-8 Wesley Terrace, Castleside | Wannop Developments Ltd - amounts by others, excl. VAT
A4: DISCLAIMER: This information is supplied in good faith for guidance and coordination only. It is not part of the Nudura ICF price and must be checked and verified by the appropriate professional (quantity surveyor, designer, engineer or supplier) before use. Only the Nudura ICF formwork and associated accessories are included in our price. Quantities are measured from the quotation models and the SK11A drawings (DRAFT); no allowance for waste is included unless stated. Quantities are per block for each block type; the Site total multiplies by the number of blocks. Rates and amounts are by others.
A6: Bill | B6: Section | C6: Description | D6: Supply £ | E6: Install £ | F6: Total £
A7: 1 | B7: 1A | C7: Brick slip system over ICF - units 01-15 (NRM2 21 / package CLD) | D7: ='Bill 1 External Finishes'!K40 | E7: ='Bill 1 External Finishes'!L40 | F7: ='Bill 1 External Finishes'!M40
A8: 1 | B8: 1B | C8: Stone slip / thin stone veneer system over ICF - units 16-18, block B08 (NRM2 21 / package CLD) | D8: ='Bill 1 External Finishes'!K41 | E8: ='Bill 1 External Finishes'!L41 | F8: ='Bill 1 External Finishes'!M41
A9: 1 | B9: 1C | C9: Sloping plots - finishes and protection below DPC (PROVISIONAL; NRM2 21 / 17) | D9: ='Bill 1 External Finishes'!K42 | E9: ='Bill 1 External Finishes'!L42 | F9: ='Bill 1 External Finishes'!M42
A10: 1 | B10: 1D | C10: Coordination items (supply by others) | D10: ='Bill 1 External Finishes'!K43 | E10: ='Bill 1 External Finishes'!L43 | F10: ='Bill 1 External Finishes'!M43
A11: Bill 1 - External Wall Finishes - Brick & Stone Slips (package CLD) | D11: ='Bill 1 External Finishes'!K44 | E11: ='Bill 1 External Finishes'!L44 | F11: ='Bill 1 External Finishes'!M44
A12: 2 | B12: 2A | C12: Plasterboard wall linings (NRM2 28 / package DRY) | D12: ='Bill 2 Internal Linings'!K37 | E12: ='Bill 2 Internal Linings'!L37 | F12: ='Bill 2 Internal Linings'!M37
A13: 2 | B13: 2B | C13: Plasterboard ceilings (NRM2 28 / package DRY) | D13: ='Bill 2 Internal Linings'!K38 | E13: ='Bill 2 Internal Linings'!L38 | F13: ='Bill 2 Internal Linings'!M38
A14: 2 | B14: 2C | C14: Jointing, beads and skim (NRM2 28 / package DRY) | D14: ='Bill 2 Internal Linings'!K39 | E14: ='Bill 2 Internal Linings'!L39 | F14: ='Bill 2 Internal Linings'!M39
A15: Bill 2 - Internal Linings - Plasterboard, Tape, Beads & Skim (package DRY) | D15: ='Bill 2 Internal Linings'!K40 | E15: ='Bill 2 Internal Linings'!L40 | F15: ='Bill 2 Internal Linings'!M40
A16: 3 | B16: 3A | C16: Internal doorsets (NRM2 24 / package JOI) | D16: ='Bill 3 Doors'!K28 | E16: ='Bill 3 Doors'!L28 | F16: ='Bill 3 Doors'!M28
A17: 3 | B17: 3B | C17: Ironmongery (NRM2 24 / package JOI) | D17: ='Bill 3 Doors'!K29 | E17: ='Bill 3 Doors'!L29 | F17: ='Bill 3 Doors'!M29
A18: 3 | B18: 3C | C18: External doorsets and windows (for information - supply by the window / door package) | D18: ='Bill 3 Doors'!K30 | E18: ='Bill 3 Doors'!L30 | F18: ='Bill 3 Doors'!M30
A19: Bill 3 - Internal Doors & Ironmongery (package JOI) | D19: ='Bill 3 Doors'!K31 | E19: ='Bill 3 Doors'!L31 | F19: ='Bill 3 Doors'!M31
A20: 4 | B20: 4A | C20: Skirtings (NRM2 22 / package JOI) | D20: ='Bill 4 Joinery'!K40 | E20: ='Bill 4 Joinery'!L40 | F20: ='Bill 4 Joinery'!M40
A21: 4 | B21: 4B | C21: Architraves (NRM2 22 / package JOI) | D21: ='Bill 4 Joinery'!K41 | E21: ='Bill 4 Joinery'!L41 | F21: ='Bill 4 Joinery'!M41
A22: 4 | B22: 4C | C22: Window boards (NRM2 22 / package JOI) | D22: ='Bill 4 Joinery'!K42 | E22: ='Bill 4 Joinery'!L42 | F22: ='Bill 4 Joinery'!M42
A23: 4 | B23: 4D | C23: Loft access (NRM2 22 / package JOI) | D23: ='Bill 4 Joinery'!K43 | E23: ='Bill 4 Joinery'!L43 | F23: ='Bill 4 Joinery'!M43
A24: Bill 4 - Joinery - Skirtings, Architraves, Window Boards & Loft Hatches (package JOI) | D24: ='Bill 4 Joinery'!K44 | E24: ='Bill 4 Joinery'!L44 | F24: ='Bill 4 Joinery'!M44
A25: 5 | B25: 5A | C25: Timber stud partitions, non-loadbearing - framing (NRM2 16 / package JOI) | D25: ='Bill 5 Partitions'!K42 | E25: ='Bill 5 Partitions'!L42 | F25: ='Bill 5 Partitions'!M42
A26: 5 | B26: 5B | C26: Partition timber - supply (NRM2 16 / package JOI) | D26: ='Bill 5 Partitions'!K43 | E26: ='Bill 5 Partitions'!L43 | F26: ='Bill 5 Partitions'!M43
A27: 5 | B27: 5C | C27: Forming door openings in partitions (NRM2 16 / package JOI) | D27: ='Bill 5 Partitions'!K44 | E27: ='Bill 5 Partitions'!L44 | F27: ='Bill 5 Partitions'!M44
A28: 5 | B28: 5D | C28: Pattresses, noggins to floor and roof structure, head restraint (NRM2 16 / package JOI) | D28: ='Bill 5 Partitions'!K45 | E28: ='Bill 5 Partitions'!L45 | F28: ='Bill 5 Partitions'!M45
A29: 5 | B29: 5E | C29: Fixings and sundries (NRM2 16 / package JOI) | D29: ='Bill 5 Partitions'!K46 | E29: ='Bill 5 Partitions'!L46 | F29: ='Bill 5 Partitions'!M46
A30: Bill 5 - Timber Stud Partitions - Framing, Openings, Pattresses & Fixings (package JOI) | D30: ='Bill 5 Partitions'!K47 | E30: ='Bill 5 Partitions'!L47 | F30: ='Bill 5 Partitions'!M47
A31: TOTAL - finishes / ancillary trades, net (agrees with the Cover overview) | D31: =D11+D15+D19+D24+D30 | E31: =E11+E15+E19+E24+E30 | F31: =F11+F15+F19+F24+F30
A33: Schedules A to D are reference schedules and are not priced. Preliminaries, overheads & profit, contingency and the ICF package (BuildEase BOQ Builder) are applied on the Cover.

Sheet Bill 1 External Finishes
C1: Bill 1 - External Wall Finishes - Brick & Stone Slips
C2: Finishes applied to the outer face of the ICF walls: brick slips to units 01-15, stone slips to units 16-18 (SK11A). [NRM2 21 / package CLD]
A4: DISCLAIMER: This information is supplied in good faith for guidance and coordination only. It is not part of the Nudura ICF price and must be checked and verified by the appropriate professional (quantity surveyor, designer, engineer or supplier) before use. Only the Nudura ICF formwork and associated accessories are included in our price. Quantities are measured from the quotation models and the SK11A drawings (DRAFT); no allowance for waste is included unless stated. Quantities are per block for each block type; the Site total multiplies by the number of blocks. Rates and amounts are by others.
A6: Ref | B6: Description | C6: Unit | D6: T01_SEMI per block | E6: T01_TER3 brick per block | F6: T01_TER3 stone per block | G6: T02_BUNG per block | H6: Site total qty | I6: Supply rate £ | J6: Install rate £ | K6: Supply £ | L6: Install £ | M6: Line total £ | N6: Notes
B7: Number of blocks of each type (Site total = per-block qty x blocks) | D7: 2 | E7: 3 | F7: 1 | G7: 2 | H7: =SUM(D7:G7) | N7: Blocks: T01_SEMI = B01, B04 (plots 01-02, 09-10); T01_TER3 brick = B02, B03, B05 (plots 03-08, 11-13); T01_TER3 stone = B08 (plots 16-18); T02_BUNG = B06, B07 (plots 14, 15)
A8: 1A Brick slip system over ICF - units 01-15 (NRM2 21 / package CLD)
B9: Brick slip system applied to the outer EPS face of the Nudura ICF (e.g. adhesive-fixed slips on a reinforced base coat, or a rail / board system - product, colour and fixing to match the SK11A brick and to be confirmed with the system supplier). Measured net of structural openings from DPC (FFL - 150) to the eaves soffit (5,320 HT01 / 2,320 HT02) and the gable rake to the drawn brick apex (8,255).
A10: 1A.1 | B10: Brick slips to walls, Front elevation, net of openings | C10: m2 | D10: 48.513 | E10: 71.676 | G10: 21.997 | H10: =SUMPRODUCT($D$7:$G$7,D10:G10) | K10: =N(H10)*N(I10) | L10: =N(H10)*N(J10) | M10: =K10+L10 | N10: Order guide +10% = 391.7; DPC (FFL-150) to eaves / verge
A11: 1A.2 | B11: Brick slips to walls, Rear elevation, net of openings | C11: m2 | D11: 47.982 | E11: 70.88 | G11: 17.006 | H11: =SUMPRODUCT($D$7:$G$7,D11:G11) | K11: =N(H11)*N(I11) | L11: =N(H11)*N(J11) | M11: =K11+L11 | N11: Order guide +10% = 376.9; DPC (FFL-150) to eaves / verge
A12: 1A.3 | B12: Brick slips to walls, Gable elevations (end units, incl. gable triangle to the drawn apex), net of openings | C12: m2 | D12: 138.056 | E12: 138.056 | H12: =SUMPRODUCT($D$7:$G$7,D12:G12) | K12: =N(H12)*N(I12) | L12: =N(H12)*N(J12) | M12: =K12+L12 | N12: Order guide +10% = 759.3; DPC (FFL-150) to eaves / verge
A13: 1A.4 | B13: Brick slips to walls, Side elevations (bungalow, hipped roof), net of openings | C13: m2 | G13: 35.815 | H13: =SUMPRODUCT($D$7:$G$7,D13:G13) | K13: =N(H13)*N(I13) | L13: =N(H13)*N(J13) | M13: =K13+L13 | N13: Order guide +10% = 78.8; DPC (FFL-150) to eaves / verge
A14: 1A.5 | B14: Brick slips to reveal returns, jambs and heads, 144 mm girth (frame set back 1/3) | C14: m2 | D14: 9.439 | E14: 14.158 | G14: 4.948 | H14: =SUMPRODUCT($D$7:$G$7,D14:G14) | K14: =N(H14)*N(I14) | L14: =N(H14)*N(J14) | M14: =K14+L14 | N14: Order guide +10% = 78.4
A15: 1A.6 | B15: Brick corner (L-shaped) slips, building external corners | C15: m | D15: 21.88 | E15: 21.88 | G15: 9.88 | H15: =SUMPRODUCT($D$7:$G$7,D15:G15) | K15: =N(H15)*N(I15) | L15: =N(H15)*N(J15) | M15: =K15+L15 | N15: Order guide +5% = 135.6
A16: 1A.7 | B16: Brick corner slips / reveal returns at window and door jambs and heads | C16: m | D16: 65.76 | E16: 98.64 | G16: 34.47 | H16: =SUMPRODUCT($D$7:$G$7,D16:G16) | K16: =N(H16)*N(I16) | L16: =N(H16)*N(J16) | M16: =K16+L16 | N16: Order guide +5% = 521.2
A17: 1A.8 | B17: Base support rail / starter track at DPC level, incl. weep / drip detail | C17: m | D17: 43.4 | E17: 54.75 | G17: 38.6 | H17: =SUMPRODUCT($D$7:$G$7,D17:G17) | K17: =N(H17)*N(I17) | L17: =N(H17)*N(J17) | M17: =K17+L17 | N17: Order guide +10% = 361.1
A18: 1A.9 | B18: Head closure / stop trim at eaves soffit and along the gable verge rake | C18: m | D18: 46.479 | E18: 57.829 | G18: 38.6 | H18: =SUMPRODUCT($D$7:$G$7,D18:G18) | K18: =N(H18)*N(I18) | L18: =N(H18)*N(J18) | M18: =K18+L18 | N18: Order guide +10% = 378.0
A19: 1A.10 | B19: Vertical movement joint at each party-wall line, front and rear faces, full height: backer rod and sealant | C19: m | D19: 10.94 | E19: 21.88 | H19: =SUMPRODUCT($D$7:$G$7,D19:G19) | K19: =N(H19)*N(I19) | L19: =N(H19)*N(J19) | M19: =K19+L19 | N19: Positions / spacing to the slip-system supplier (add intermediate joints if required)
A20: 1B Stone slip / thin stone veneer system over ICF - units 16-18, block B08 (NRM2 21 / package CLD)
B21: Natural or reconstituted stone slip (thin veneer) system to match the SK11A stone elevations for units 16-18 (block B08), adhesive or rail fixed over the ICF EPS face. Product, coursing, weight and fixing to be confirmed with the supplier and the structural engineer. Measured as 1A.
A22: 1B.1 | B22: Stone slips to walls, Front elevation, net of openings | C22: m2 | F22: 71.676 | H22: =SUMPRODUCT($D$7:$G$7,D22:G22) | K22: =N(H22)*N(I22) | L22: =N(H22)*N(J22) | M22: =K22+L22 | N22: Order guide +10% = 78.8; DPC (FFL-150) to eaves / verge
A23: 1B.2 | B23: Stone slips to walls, Rear elevation, net of openings | C23: m2 | F23: 70.88 | H23: =SUMPRODUCT($D$7:$G$7,D23:G23) | K23: =N(H23)*N(I23) | L23: =N(H23)*N(J23) | M23: =K23+L23 | N23: Order guide +10% = 78.0; DPC (FFL-150) to eaves / verge
A24: 1B.3 | B24: Stone slips to walls, Gable elevations (end units, incl. gable triangle to the drawn apex), net of openings | C24: m2 | F24: 138.056 | H24: =SUMPRODUCT($D$7:$G$7,D24:G24) | K24: =N(H24)*N(I24) | L24: =N(H24)*N(J24) | M24: =K24+L24 | N24: Order guide +10% = 151.9; DPC (FFL-150) to eaves / verge
A25: 1B.4 | B25: Stone slips to reveal returns, jambs and heads, 149 mm girth (frame set back 1/3) | C25: m2 | F25: 14.651 | H25: =SUMPRODUCT($D$7:$G$7,D25:G25) | K25: =N(H25)*N(I25) | L25: =N(H25)*N(J25) | M25: =K25+L25 | N25: Order guide +10% = 16.1
A26: 1B.5 | B26: Stone corner (L-shaped) slips, building external corners | C26: m | F26: 21.88 | H26: =SUMPRODUCT($D$7:$G$7,D26:G26) | K26: =N(H26)*N(I26) | L26: =N(H26)*N(J26) | M26: =K26+L26 | N26: Order guide +5% = 23.0
A27: 1B.6 | B27: Stone corner slips / reveal returns at window and door jambs and heads | C27: m | F27: 98.64 | H27: =SUMPRODUCT($D$7:$G$7,D27:G27) | K27: =N(H27)*N(I27) | L27: =N(H27)*N(J27) | M27: =K27+L27 | N27: Order guide +5% = 103.6
A28: 1B.7 | B28: Base support rail / starter track at DPC level, incl. weep / drip detail | C28: m | F28: 54.75 | H28: =SUMPRODUCT($D$7:$G$7,D28:G28) | K28: =N(H28)*N(I28) | L28: =N(H28)*N(J28) | M28: =K28+L28 | N28: Order guide +10% = 60.2
A29: 1B.8 | B29: Head closure / stop trim at eaves soffit and along the gable verge rake | C29: m | F29: 57.829 | H29: =SUMPRODUCT($D$7:$G$7,D29:G29) | K29: =N(H29)*N(I29) | L29: =N(H29)*N(J29) | M29: =K29+L29 | N29: Order guide +10% = 63.6
A30: 1B.9 | B30: Vertical movement joint at each party-wall line, front and rear faces, full height: backer rod and sealant | C30: m | F30: 21.88 | H30: =SUMPRODUCT($D$7:$G$7,D30:G30) | K30: =N(H30)*N(I30) | L30: =N(H30)*N(J30) | M30: =K30+L30 | N30: Positions / spacing to the slip-system supplier (add intermediate joints if required)
A31: 1C Sloping plots - finishes and protection below DPC (PROVISIONAL; NRM2 21 / 17)
B32: From the existing survey levels at each block corner (10G) and the stepped-footing rule FFL = mean corner ground + 150. Final external levels are not designed - re-measure on the engineer's / architect's finished levels. Per-block figures in Schedule D.
A33: 1C.1 | B33: Exposed ICF face between DPC and existing ground on the low (fill) side: continue the slip finish down to finished ground (or below-DPC plinth finish / protection board) | C33: m2 | H33: 83.31 | K33: =N(H33)*N(I33) | L33: =N(H33)*N(J33) | M33: =K33+L33 | N33: B01 9.7; B02 8.9; B03 15.1; B04 2.7; B05 16.4; B06 6.1; B07 9.5; B08 14.9
A34: 1C.2 | B34: Ground above DPC against the ICF on the high (cut) side: waterproofing / tanking to the ICF face, protection board and perimeter drainage - or regrade to 150 below DPC | C34: m2 | H34: 83.31 | K34: =N(H34)*N(I34) | L34: =N(H34)*N(J34) | M34: =K34+L34 | N34: B01 9.7; B02 8.9; B03 15.1; B04 2.7; B05 16.4; B06 6.1; B07 9.5; B08 14.9
A35: 1D Coordination items (supply by others)
A36: 1D.1 | B36: External window cills, measured at structural opening width (for coordination with the window package) | C36: m | D36: 14.52 | E36: 21.78 | F36: 21.78 | G36: 6.24 | H36: =SUMPRODUCT($D$7:$G$7,D36:G36) | K36: =N(H36)*N(I36) | L36: =N(H36)*N(J36) | M36: =K36+L36 | N36: By window supplier - coordination only
A38: PACKAGE SUMMARY - Bill 1 External Wall Finishes - Brick & Stone Slips (package CLD; amounts by others, excl. VAT)
A39: Section | B39: Description | K39: Supply £ | L39: Install £ | M39: Total £
A40: 1A | B40: Brick slip system over ICF - units 01-15 (NRM2 21 / package CLD) | K40: =SUM(K9:K19) | L40: =SUM(L9:L19) | M40: =SUM(M9:M19)
A41: 1B | B41: Stone slip / thin stone veneer system over ICF - units 16-18, block B08 (NRM2 21 / package CLD) | K41: =SUM(K21:K30) | L41: =SUM(L21:L30) | M41: =SUM(M21:M30)
A42: 1C | B42: Sloping plots - finishes and protection below DPC (PROVISIONAL; NRM2 21 / 17) | K42: =SUM(K32:K34) | L42: =SUM(L32:L34) | M42: =SUM(M32:M34)
A43: 1D | B43: Coordination items (supply by others) | K43: =SUM(K36:K36) | L43: =SUM(L36:L36) | M43: =SUM(M36:M36)
...

Sheet Bill 2 Internal Linings
C1: Bill 2 - Internal Linings - Plasterboard, Tape, Beads & Skim
C2: Dry linings to the inside faces of the ICF walls, party walls, timber partitions, ceilings, reveals and stair. [NRM2 28 / package DRY]
A4: DISCLAIMER: This information is supplied in good faith for guidance and coordination only. It is not part of the Nudura ICF price and must be checked and verified by the appropriate professional (quantity surveyor, designer, engineer or supplier) before use. Only the Nudura ICF formwork and associated accessories are included in our price. Quantities are measured from the quotation models and the SK11A drawings (DRAFT); no allowance for waste is included unless stated. Quantities are per block for each block type; the Site total multiplies by the number of blocks. Rates and amounts are by others.
A6: Ref | B6: Description | C6: Unit | D6: T01_SEMI per block | E6: T01_TER3 brick per block | F6: T01_TER3 stone per block | G6: T02_BUNG per block | H6: Site total qty | I6: Supply rate £ | J6: Install rate £ | K6: Supply £ | L6: Install £ | M6: Line total £ | N6: Notes
B7: Number of blocks of each type (Site total = per-block qty x blocks) | D7: 2 | E7: 3 | F7: 1 | G7: 2 | H7: =SUM(D7:G7) | N7: Blocks: T01_SEMI = B01, B04 (plots 01-02, 09-10); T01_TER3 brick = B02, B03, B05 (plots 03-08, 11-13); T01_TER3 stone = B08 (plots 16-18); T02_BUNG = B06, B07 (plots 14, 15)
A8: 2A Plasterboard wall linings (NRM2 28 / package DRY)
B9: Measured net on the finished room faces, per unit and summed per block. Heights: HT01 GF 0 to u/s FF joists 2,425; HT01 FF deck 2,700 to u/s truss chords 5,370 (2,670); HT02 0 to u/s truss chords 2,336. Openings deducted (external openings once; internal door gaps on both faces). Board types are proposals - confirm with the board supplier; ICF faces need mechanical fixings into the webs.
A10: 2A.1 | B10: GF external walls - internal face of the ICF: 12.5 mm wallboard, adhesive dabs + mechanical fixings to the ICF webs (MR board in WC) | C10: m2 | D10: 74.938 | E10: 90.644 | F10: 90.644 | G10: 61.054 | H10: =SUMPRODUCT($D$7:$G$7,D10:G10) | K10: =N(H10)*N(I10) | L10: =N(H10)*N(J10) | M10: =K10+L10 | N10: Order guide +10% = 698.0
A11: 2A.2 | B11: FF external walls - internal face of the ICF (HT01): 12.5 mm wallboard as above (MR board in bathroom) | C11: m2 | D11: 91.816 | E11: 114.078 | F11: 114.078 | H11: =SUMPRODUCT($D$7:$G$7,D11:G11) | K11: =N(H11)*N(I11) | L11: =N(H11)*N(J11) | M11: =K11+L11 | N11: Order guide +10% = 703.9
A12: 2A.3 | B12: GF party walls (ICF 6in Std) - each house side: 15 mm sound / fire board on dabs per the ICF separating-wall detail (confirm robust detail) | C12: m2 | D12: 44.808 | E12: 89.037 | F12: 89.037 | H12: =SUMPRODUCT($D$7:$G$7,D12:G12) | K12: =N(H12)*N(I12) | L12: =N(H12)*N(J12) | M12: =K12+L12 | N12: Order guide +10% = 490.3
A13: 2A.4 | B13: FF party walls (ICF 6in Std) - each house side: 15 mm sound / fire board as above | C13: m2 | D13: 48.7 | E13: 96.764 | F13: 96.764 | H13: =SUMPRODUCT($D$7:$G$7,D13:G13) | K13: =N(H13)*N(I13) | L13: =N(H13)*N(J13) | M13: =K13+L13 | N13: Order guide +10% = 532.9
A14: 2A.5 | B14: GF timber stud partitions - both faces: 15 mm board on 38 x 89 studs (119 build-up); MR in wet rooms | C14: m2 | D14: 47.522 | E14: 71.406 | F14: 71.406 | G14: 95.627 | H14: =SUMPRODUCT($D$7:$G$7,D14:G14) | K14: =N(H14)*N(I14) | L14: =N(H14)*N(J14) | M14: =K14+L14 | N14: Order guide +10% = 629.1
A15: 2A.6 | B15: FF timber stud partitions - both faces: 15 mm board on 38 x 89 studs (119 build-up); MR in wet rooms | C15: m2 | D15: 178.146 | E15: 267.422 | F15: 267.422 | H15: =SUMPRODUCT($D$7:$G$7,D15:G15) | K15: =N(H15)*N(I15) | L15: =N(H15)*N(J15) | M15: =K15+L15 | N15: Order guide +10% = 1,568.6
A16: 2A.7 | B16: Under-stair spandrel / store closing panel - both faces (HT01): 12.5 mm board on 38 x 63 framing (framing by the stair installer) | C16: m2 | D16: 8.923 | E16: 13.446 | F16: 13.446 | H16: =SUMPRODUCT($D$7:$G$7,D16:G16) | K16: =N(H16)*N(I16) | L16: =N(H16)*N(J16) | M16: =K16+L16 | N16: Order guide +10% = 78.8
